[2025-04-10T17:45:57.177+0000] {taskinstance.py:1956} INFO - Dependencies all met for dep_context=non-requeueable deps ti=<TaskInstance: isoloops_ingest.load_to_snowflake manual__2025-04-10T17:45:54.342423+00:00 [queued]>
[2025-04-10T17:45:57.181+0000] {taskinstance.py:1956} INFO - Dependencies all met for dep_context=requeueable deps ti=<TaskInstance: isoloops_ingest.load_to_snowflake manual__2025-04-10T17:45:54.342423+00:00 [queued]>
[2025-04-10T17:45:57.181+0000] {taskinstance.py:2170} INFO - Starting attempt 1 of 1
[2025-04-10T17:45:57.186+0000] {taskinstance.py:2191} INFO - Executing <Task(PythonOperator): load_to_snowflake> on 2025-04-10 17:45:54.342423+00:00
[2025-04-10T17:45:57.190+0000] {standard_task_runner.py:60} INFO - Started process 148 to run task
[2025-04-10T17:45:57.194+0000] {standard_task_runner.py:87} INFO - Running: ['***', 'tasks', 'run', 'isoloops_ingest', 'load_to_snowflake', 'manual__2025-04-10T17:45:54.342423+00:00', '--job-id', '98', '--raw', '--subdir', 'DAGS_FOLDER/isoloops_ingest.py', '--cfg-path', '/tmp/tmpfp9coyfd']
[2025-04-10T17:45:57.195+0000] {standard_task_runner.py:88} INFO - Job 98: Subtask load_to_snowflake
[2025-04-10T17:45:57.216+0000] {task_command.py:423} INFO - Running <TaskInstance: isoloops_ingest.load_to_snowflake manual__2025-04-10T17:45:54.342423+00:00 [running]> on host eea5da768a45
[2025-04-10T17:45:57.245+0000] {taskinstance.py:2480} INFO - Exporting env vars: AIRFLOW_CTX_DAG_OWNER='***' AIRFLOW_CTX_DAG_ID='isoloops_ingest' AIRFLOW_CTX_TASK_ID='load_to_snowflake' AIRFLOW_CTX_EXECUTION_DATE='2025-04-10T17:45:54.342423+00:00' AIRFLOW_CTX_TRY_NUMBER='1' AIRFLOW_CTX_DAG_RUN_ID='manual__2025-04-10T17:45:54.342423+00:00'
[2025-04-10T17:45:58.037+0000] {taskinstance.py:2698} ERROR - Task failed with exception
Traceback (most recent call last):
  File "/home/airflow/.local/lib/python3.8/site-packages/airflow/models/taskinstance.py", line 433, in _execute_task
    result = execute_callable(context=context, **execute_callable_kwargs)
  File "/home/airflow/.local/lib/python3.8/site-packages/airflow/operators/python.py", line 199, in execute
    return_value = self.execute_callable()
  File "/home/airflow/.local/lib/python3.8/site-packages/airflow/operators/python.py", line 216, in execute_callable
    return self.python_callable(*self.op_args, **self.op_kwargs)
  File "/opt/airflow/dags/isoloops_ingest.py", line 22, in run_loader
    subprocess.run(["python3", "/opt/airflow/dags/load_to_snowflake.py"], check=True)
  File "/usr/local/lib/python3.8/subprocess.py", line 516, in run
    raise CalledProcessError(retcode, process.args,
subprocess.CalledProcessError: Command '['python3', '/opt/airflow/dags/load_to_snowflake.py']' returned non-zero exit status 1.
[2025-04-10T17:45:58.052+0000] {taskinstance.py:1138} INFO - Marking task as FAILED. dag_id=isoloops_ingest, task_id=load_to_snowflake, execution_date=20250410T174554, start_date=20250410T174557, end_date=20250410T174558
[2025-04-10T17:45:58.064+0000] {standard_task_runner.py:107} ERROR - Failed to execute job 98 for task load_to_snowflake (Command '['python3', '/opt/airflow/dags/load_to_snowflake.py']' returned non-zero exit status 1.; 148)
[2025-04-10T17:45:58.118+0000] {local_task_job_runner.py:234} INFO - Task exited with return code 1
[2025-04-10T17:45:58.138+0000] {taskinstance.py:3280} INFO - 0 downstream tasks scheduled from follow-on schedule check
