[2025-04-13T00:00:03.308+0000] {taskinstance.py:1956} INFO - Dependencies all met for dep_context=non-requeueable deps ti=<TaskInstance: rag_daily_discovery.run_discovery_flow scheduled__2025-04-12T00:00:00+00:00 [queued]>
[2025-04-13T00:00:03.314+0000] {taskinstance.py:1956} INFO - Dependencies all met for dep_context=requeueable deps ti=<TaskInstance: rag_daily_discovery.run_discovery_flow scheduled__2025-04-12T00:00:00+00:00 [queued]>
[2025-04-13T00:00:03.314+0000] {taskinstance.py:2170} INFO - Starting attempt 1 of 1
[2025-04-13T00:00:03.320+0000] {taskinstance.py:2191} INFO - Executing <Task(PythonOperator): run_discovery_flow> on 2025-04-12 00:00:00+00:00
[2025-04-13T00:00:03.326+0000] {standard_task_runner.py:60} INFO - Started process 6742 to run task
[2025-04-13T00:00:03.334+0000] {standard_task_runner.py:87} INFO - Running: ['***', 'tasks', 'run', 'rag_daily_discovery', 'run_discovery_flow', 'scheduled__2025-04-12T00:00:00+00:00', '--job-id', '205', '--raw', '--subdir', 'DAGS_FOLDER/rag_daily_discovery.py', '--cfg-path', '/tmp/tmpzkcbb66_']
[2025-04-13T00:00:03.336+0000] {standard_task_runner.py:88} INFO - Job 205: Subtask run_discovery_flow
[2025-04-13T00:00:03.368+0000] {task_command.py:423} INFO - Running <TaskInstance: rag_daily_discovery.run_discovery_flow scheduled__2025-04-12T00:00:00+00:00 [running]> on host cea305b355c8
[2025-04-13T00:00:03.403+0000] {taskinstance.py:2480} INFO - Exporting env vars: AIRFLOW_CTX_DAG_OWNER='***' AIRFLOW_CTX_DAG_ID='rag_daily_discovery' AIRFLOW_CTX_TASK_ID='run_discovery_flow' AIRFLOW_CTX_EXECUTION_DATE='2025-04-12T00:00:00+00:00' AIRFLOW_CTX_TRY_NUMBER='1' AIRFLOW_CTX_DAG_RUN_ID='scheduled__2025-04-12T00:00:00+00:00'
[2025-04-13T00:00:03.716+0000] {taskinstance.py:2698} ERROR - Task failed with exception
Traceback (most recent call last):
  File "/home/airflow/.local/lib/python3.8/site-packages/airflow/models/taskinstance.py", line 433, in _execute_task
    result = execute_callable(context=context, **execute_callable_kwargs)
  File "/home/airflow/.local/lib/python3.8/site-packages/airflow/operators/python.py", line 199, in execute
    return_value = self.execute_callable()
  File "/home/airflow/.local/lib/python3.8/site-packages/airflow/operators/python.py", line 216, in execute_callable
    return self.python_callable(*self.op_args, **self.op_kwargs)
  File "/opt/airflow/dags/rag_daily_discovery.py", line 15, in discovery_flow
    queries = generate_sample_queries()
  File "/opt/airflow/backend/rag_pipeline/generate_sample_targets.py", line 17, in generate_sample_queries
    response = client.chat.completions.create(
  File "/home/airflow/.local/lib/python3.8/site-packages/openai/_utils/_utils.py", line 279, in wrapper
    return func(*args, **kwargs)
  File "/home/airflow/.local/lib/python3.8/site-packages/openai/resources/chat/completions/completions.py", line 914, in create
    return self._post(
  File "/home/airflow/.local/lib/python3.8/site-packages/openai/_base_client.py", line 1242, in post
    return cast(ResponseT, self.request(cast_to, opts, stream=stream, stream_cls=stream_cls))
  File "/home/airflow/.local/lib/python3.8/site-packages/openai/_base_client.py", line 919, in request
    return self._request(
  File "/home/airflow/.local/lib/python3.8/site-packages/openai/_base_client.py", line 1023, in _request
    raise self._make_status_error_from_response(err.response) from None
openai.AuthenticationError: Error code: 401 - {'error': {'message': 'Incorrect API key provided: sk-proj-********************************************************************************************************************************************************9xcA. You can find your API key at https://platform.openai.com/account/api-keys.', 'type': 'invalid_request_error', 'param': None, 'code': 'invalid_api_key'}}
[2025-04-13T00:00:03.736+0000] {taskinstance.py:1138} INFO - Marking task as FAILED. dag_id=rag_daily_discovery, task_id=run_discovery_flow, execution_date=20250412T000000, start_date=20250413T000003, end_date=20250413T000003
[2025-04-13T00:00:03.746+0000] {standard_task_runner.py:107} ERROR - Failed to execute job 205 for task run_discovery_flow (Error code: 401 - {'error': {'message': 'Incorrect API key provided: sk-proj-********************************************************************************************************************************************************9xcA. You can find your API key at https://platform.openai.com/account/api-keys.', 'type': 'invalid_request_error', 'param': None, 'code': 'invalid_api_key'}}; 6742)
[2025-04-13T00:00:03.774+0000] {local_task_job_runner.py:234} INFO - Task exited with return code 1
[2025-04-13T00:00:03.802+0000] {taskinstance.py:3280} INFO - 0 downstream tasks scheduled from follow-on schedule check
